<?xml version="1.0" ?>

<robot name="Movee">

<!--Matrix computation macros-->
  <macro name="cylinder_inertia" params="m r h">
        <inertia  ixx="${m*(3*r*r+h*h)/12}" ixy = "0" ixz = "0"
                  iyy="${m*(3*r*r+h*h)/12}" iyz = "0"
                  izz="${m*r*r/2}" /> 
  </macro>

  <macro name="box_inertia" params="m x y z">
        <inertia  ixx="${m*(y*y+z*z)/12}" ixy = "0" ixz = "0"
                  iyy="${m*(x*x+z*z)/12}" iyz = "0"
                  izz="${m*(x*x+z*z)/12}" /> 
  </macro>

  <macro name="sphere_inertia" params="m r">
        <inertia  ixx="${2*m*r*r/5}" ixy = "0" ixz = "0"
                  iyy="${2*m*r*r/5}" iyz = "0"
                  izz="${2*m*r*r/5}" /> 
  </macro>

  
  <!-- <xacro:include filename="$(find movee_description)/urdf/friction.xacro"/>
  <xacro:arg name="training_wheels" default="true" />

  <xacro:property name="wheel_mass" value="0.5" />
  <xacro:property name="wheel_radius" value="0.1" />
  <xacro:property name="wheel_thickness" value="0.05" />
  <xacro:property name="wheelbase" value="0.5" />
  <xacro:property name="thigh_length" value="0.4" />
  <xacro:property name="thigh_conrod_length" value="0.5" />
  <xacro:property name="calf_length" value="0.4" />

  <xacro:property name="body_mass" value="10" />
 
  <xacro:property name="depth_camera_name" value="Creative"/>
  <xacro:property name="depth_camera_mass" value="0.1"/> -->
    
<!-- ############################################################################################# -->
 <!-- ############################ Joint and Transmissions definition ############################ -->

<!-- Dummy joint for KDL -->
  <joint name="base_to_chassis" type="fixed">
    <parent link="base_link"/>
    <child link="chassis_link"/>
    <origin xyz="0 0 0"/>
  </joint>
 
<!-- Knees -->
  <joint name="knee_pivot_right" type="revolute">
    <parent link="thigh_right"/>
    <child link="calf_right"/>
    <origin rpy="1.8  0  0" xyz="0  0  -0.38"/>
    <axis xyz="1  0  0"/>
    <limit effort="-1.0" lower="0.1" upper="1" velocity="-1.0"/>
    <!-- <limit effort="-1.0" lower="-3.14" upper="3.14" velocity="-1.0"/> -->
  </joint>  
  <transmission name="knee_pivot_right_trans">
    <type>transmission_interface/SimpleTransmission</type>
    <joint name="knee_pivot_right">
      <hardwareInterface>hardware_interface/PositionJointInterface</hardwareInterface>
    </joint>
    <actuator name="knee_motor_right">
      <hardwareInterface>hardware_interface/PositionJointInterface</hardwareInterface>
      <mechanicalReduction>1</mechanicalReduction>
    </actuator>
  </transmission>
  <!-- <joint name="knee_conrod_pivot_right" type="revolute">
    <parent link="thigh_conrod_right"/>
    <child link="calf_right"/>
    <origin rpy="1.8  0  0" xyz="0  0  -0.38"/>
    <axis xyz="1  0  0"/>
    <limit effort="-1.0" lower="0.1" upper="1" velocity="-1.0"/>    
  </joint>   -->


  <joint name="knee_pivot_left" type="revolute">
    <parent link="thigh_left"/>
    <child link="calf_left"/>
    <origin rpy="1.8  0  0" xyz="0 0 -0.38"/>
    <axis xyz="1  0  0"/>
    <limit effort="-1.0" lower="0.1" upper="1" velocity="-1.0"/>
    <!-- <limit effort="-1.0" lower="-3.14" upper="3.14" velocity="-1.0"/> -->
  </joint>
  <transmission name="knee_pivot_left_trans">
    <type>transmission_interface/SimpleTransmission</type>
    <joint name="knee_pivot_left">
      <hardwareInterface>hardware_interface/PositionJointInterface</hardwareInterface>
    </joint>

    <actuator name="knee_motor_left">
      <hardwareInterface>hardware_interface/PositionJointInterface</hardwareInterface>
      <mechanicalReduction>1</mechanicalReduction>
    </actuator>
  </transmission>
    <!-- <joint name="knee_conrod_pivot_left" type="revolute">
    <parent link="thigh_conrod_left"/>
    <child link="calf_left"/>
    <origin rpy="1.8  0  0" xyz="0  0  -0.38"/>
    <axis xyz="1  0  0"/>
    <limit effort="-1.0" lower="0.1" upper="1" velocity="-1.0"/>   
  </joint>   -->

<!-- Hip -->
  <joint name="hip_pivot_right" type="revolute">
    <parent link="chassis_link"/>
    <child link="thigh_right"/>
    <origin rpy="-0.9  0  0" xyz="0.17  0  0.9"/>
    <axis xyz="1  0  0"/>
    <limit effort="-1.0" lower="0.4" upper="1" velocity="-1.0"/>
    <limit effort="-1.0" lower="-3.14" upper="3.14" velocity="-1.0"/>
  </joint>
   <transmission name="hip_pivot_right_trans">
    <type>transmission_interface/SimpleTransmission</type>
    <joint name="hip_pivot_right">
      <hardwareInterface>hardware_interface/PositionJointInterface</hardwareInterface>
    </joint>
    <actuator name="hip_motor_right">
      <hardwareInterface>hardware_interface/PositionJointInterface</hardwareInterface>
      <mechanicalReduction>1</mechanicalReduction>
    </actuator>
  </transmission>
  <joint name="hip_pivot_conrod_right" type="revolute">
    <parent link="chassis_link"/>
    <child link="thigh_conrod_right"/>
    <origin rpy="-0.9  0  0" xyz="0.17  0.0  1"/>
    <axis xyz="1  0  0"/>
    <limit effort="-1.0" lower="-3.14" upper="3.14"  velocity="-1.0"/>
    <mimic joint ="hip_pivot_right" multiplier="1" offset ="0"/>
  
  </joint>

  <joint name="hip_pivot_left" type="revolute">
    <parent link="chassis_link"/>
    <child link="thigh_left"/>
    <origin rpy="-0.9 0  0" xyz="-0.17 0  0.9"/>
    <axis xyz="1  0  0"/>
    <limit effort="-1.0" lower="0.4" upper="1"  velocity="-1.0"/>
    <limit effort="-1.0" lower="-3.14" upper="3.14" velocity="-1.0"/>
  </joint>
   <transmission name="hip_pivot_left_trans">
    <type>transmission_interface/SimpleTransmission</type>
    <joint name="hip_pivot_left">
      <hardwareInterface>hardware_interface/PositionJointInterface</hardwareInterface>
    </joint>
    <actuator name="hip_motor_left">
      <hardwareInterface>hardware_interface/PositionJointInterface</hardwareInterface>
      <mechanicalReduction>1</mechanicalReduction>
    </actuator>
  </transmission>
  <joint name="hip_pivot_conrod_left" type="revolute">
    <parent link="chassis_link"/>
    <child link="thigh_conrod_left"/>
    <origin rpy="-0.9  0  0" xyz="-0.17  0.0  1"/>
    <axis xyz="1  0  0"/>
    <limit effort="-1.0" lower="-3.14" upper="3.14"  velocity="-1.0"/>
    <mimic joint ="hip_pivot_left" multiplier="1" offset ="0"/>

  </joint>




 <!-- Wheels-->
  <joint name="wheel_pivot_right" type="continuous">
    <parent link="calf_right"/>
    <child link="wheel_right"/>
    <origin rpy="3.14159  1.56  3.14159" xyz="-0.0  0.0 -0.38"/>
    <axis xyz="0  0  1"/>
    <limit effort="-1.0"  velocity="-1.0"/>
    <!-- <limit effort="-1.0" lower="-3.14" upper="3.14" velocity="-1.0"/> -->
  </joint>
  <transmission name="wheel_pivot_right_trans">
    <type>transmission_interface/SimpleTransmission</type>
    <joint name="wheel_pivot_right">
      <hardwareInterface>hardware_interface/VelocityJointInterface</hardwareInterface>
    </joint>
    <actuator name="wheel_motor_right">
      <hardwareInterface>hardware_interface/VelocityJointInterface</hardwareInterface>
      <mechanicalReduction>1</mechanicalReduction>
    </actuator>
  </transmission>

  <joint name="wheel_pivot_left" type="continuous">
    <parent link="calf_left"/>
    <child link="wheel_left"/>
    <origin rpy="0.04  1.56  3.14159" xyz="0.0 -0.0 -0.38"/>
    <axis xyz="0   0   1"/>
    <limit effort="-1.0"  velocity="-1.0"/>
    <!-- <limit effort="-1.0" lower="-3.14" upper="3.14" velocity="-1.0"/> -->
  </joint>
  <transmission name="wheel_pivot_left_trans">
    <type>transmission_interface/SimpleTransmission</type>
    <joint name="wheel_pivot_left">
      <hardwareInterface>hardware_interface/VelocityJointInterface</hardwareInterface>
    </joint>
    <actuator name="wheel_motor_left">
      <hardwareInterface>hardware_interface/VelocityJointInterface</hardwareInterface>
      <mechanicalReduction>1</mechanicalReduction>
    </actuator>
  </transmission>

<!-- ############################################################################################# -->
<!-- ################################# Link definition ########################################### -->
 <link name="base_link">
    <!-- <visual>
      <geometry>
        <cylinder length="0.6" radius="0.2"/>
      </geometry>
    </visual> -->
  </link>

  <link name="chassis_link">
    <inertial>
      <mass value="10"/>
      <origin rpy="0  0  0" xyz="0  -0.07  0.9"/>
      <!-- <inertia ixx="0.0004" ixy="0" ixz="0" iyy="0.0004" iyz="0" izz="0.0005"/> -->
      <box_inertia m="10" x="0.3" y="0.35" z="0.25"/>
    </inertial>
    <collision name="Movee__collision">
      <origin rpy="0  0  0" xyz="0   0   0.94"/>
      <geometry>
        <box size="0.3 0.35 0.25" />
      </geometry>
    </collision>
    <visual name="Movee__visual">
      <origin rpy="0  0  0" xyz="0   -0.05   0.89"/>
      <geometry>
      <mesh filename ="package://movee_description/meshes/pelvis.dae" scale="0.001 0.001 0.001"/>
      <!-- <box size="0.3 0.35 0.25"/>  -->
      </geometry>
    </visual>    
  </link>

  <link name="thigh_right">
    <inertial>
      <mass value="0.5"/>
      <origin rpy="0  0  0" xyz="0  0  -0.2"/>
      <!-- <inertia ixx="4.9e-06" ixy="0" ixz="0" iyy="4.9e-06" iyz="0" izz="3.5e-08"/> -->
      <cylinder_inertia m="0.5" r="0.015" h="0.4"/>
    </inertial>
    <collision name="Movee__collision">
      <origin rpy="0  0  0" xyz="0    0   -0.2"/>
      <geometry>
        <cylinder length="0.41" radius="0.015"/>
      </geometry>
    </collision>
    <visual name="Movee__visual">
      <origin rpy="0  0  0" xyz="0    0   -0.2"/>
      <geometry>
        <cylinder length="0.41" radius="0.015"/>
      </geometry>
    </visual>
  </link>
  <link name="thigh_conrod_right">
    <inertial>
      <mass value="0.5"/>
      <origin rpy="0  0  0" xyz="0  0  -0.2"/>
      <!-- <inertia ixx="4.9e-06" ixy="0" ixz="0" iyy="4.9e-06" iyz="0" izz="3.5e-08"/> -->
      <cylinder_inertia m="0.5" r="0.005" h="0.45"/>
    </inertial>
    <collision name="Movee__collision">
      <origin rpy="0  0  0" xyz="0    0   -0.2"/>
      <geometry>
        <cylinder length="0.45" radius="0.005"/>
      </geometry>
    </collision>
    <visual name="Movee__visual">
      <origin rpy="0  0  0" xyz="0    0   -0.2"/>
      <geometry>
        <cylinder length="0.45" radius="0.005"/>
      </geometry>
    </visual>
  </link>
 
  <link name="thigh_left">
    <inertial>
      <mass value="0.5"/>
      <origin rpy="0  0  0" xyz="0  0  -0.2"/>
      <!-- <inertia ixx="4.9e-06" ixy="0" ixz="0" iyy="4.9e-06" iyz="0" izz="3.5e-08"/> -->
      <cylinder_inertia m="0.5" r="0.015" h="0.4"/>
    </inertial>
    <collision name="Movee__collision">
      <origin rpy="0  0  0" xyz="0    0   -0.19"/>
      <geometry>
        <cylinder length="0.41" radius="0.015"/>
      </geometry>
    </collision>
    <visual name="Movee__visual">
      <origin rpy="0  0  0" xyz="0    0   -0.19"/>
      <geometry>
        <cylinder length="0.41" radius="0.015"/>
      </geometry>
    </visual>
  </link>
    <link name="thigh_conrod_left">
    <inertial>
      <mass value="0.5"/>
      <origin rpy="0  0  0" xyz="0  0  -0.2"/>
      <!-- <inertia ixx="4.9e-06" ixy="0" ixz="0" iyy="4.9e-06" iyz="0" izz="3.5e-08"/> -->
      <cylinder_inertia m="0.5" r="0.005" h="0.45"/>
    </inertial>
    <collision name="Movee__collision">
      <origin rpy="0  0  0" xyz="0    0   -0.2"/>
      <geometry>
        <cylinder length="0.45" radius="0.005"/>
      </geometry>
    </collision>
    <visual name="Movee__visual">
      <origin rpy="0  0  0" xyz="0    0   -0.2"/>
      <geometry>
        <cylinder length="0.45" radius="0.005"/>
      </geometry>
    </visual>
  </link>

  <!-- ################################ Calves ##########################" -->
   <link name="calf_right">
    <inertial>
      <mass value="0.5"/>
      <origin rpy="0  0  0" xyz="0  0  -0.15"/>
      <!-- <inertia ixx="4.9e-06" ixy="0" ixz="0" iyy="4.9e-06" iyz="0" izz="3.5e-08"/> -->
      <cylinder_inertia m="0.5" r="0.015" h="0.4"/>
    </inertial>
    <collision name="Movee__collision">
      <origin rpy="0  0  0" xyz="0    0   -0.16"/>
      <geometry>
        <cylinder length="0.49" radius="0.06"/>
      </geometry>
    </collision>
    <visual name="Movee__visual">
      <origin rpy="0  0  0" xyz="0    0   0"/>
      <geometry>        
        <mesh filename ="package://movee_description/meshes/calfr_right.dae" scale="0.001 0.001 0.001"/>
      </geometry>
    </visual>
  </link>

  <link name="calf_left">
    <inertial>
      <mass value="0.5"/>
      <origin rpy="0  0  0" xyz="0  0  -0.15"/>
      <!-- <inertia ixx="4.9e-06" ixy="0" ixz="0" iyy="4.9e-06" iyz="0" izz="3.5e-08"/> -->
      <cylinder_inertia m="0.5" r="0.015" h="0.4"/>
    </inertial>
    <collision name="Movee__collision">
      <origin rpy="0  0  0" xyz="0    0   -0.16"/>
      <geometry>
        <cylinder length="0.49" radius="0.06"/>
      </geometry>
    </collision>
    <visual name="Movee__visual">
      <origin rpy="0  0  0" xyz="0    0   0"/>
      <geometry>
        <mesh filename ="package://movee_description/meshes/calfr_left.dae" scale="0.001 0.001 0.001"/>
      </geometry>
    </visual>
  </link>
  <link name="wheel_right">
    <inertial>
      <mass value="1.2"/>
      <origin rpy="0  0  0" xyz="0  0  0.055"/>
      <!-- <inertia ixx="5.89e-06" ixy="0" ixz="0" iyy="5.89e-06" iyz="0" izz="1.12e-05"/> -->
      <cylinder_inertia m="1.5" r="0.1" h="0.05"/>
    </inertial>
    <collision name="Movee__collision">
      <origin rpy="0  0  0" xyz="0    0    0.055"/>
      <geometry>
        <cylinder length="0.05" radius="0.1"/>
      </geometry>
    </collision>
    <visual name="Movee__visual">
      <origin rpy="0  0  0" xyz="0    0    0.065"/>
      <geometry>
        <mesh filename ="package://movee_description/meshes/wheelp.dae" scale="0.001 0.001 0.001"/>
        <!-- <cylinder length="0.05" radius="0.1"/> -->
      </geometry>
    </visual>
  </link>
  <link name="wheel_left">
    <inertial>
      <mass value="1.2"/>
      <origin rpy="0  0  0" xyz="0  0  -0.055"/>
      <!-- <inertia ixx="5.8e-06" ixy="0" ixz="0" iyy="5.8e-06" iyz="0" izz="1.1e-05"/> -->
      <cylinder_inertia m="1.5" r="0.1" h="0.05"/>
    </inertial>
    <collision name="Movee__collision">
      <origin rpy="0  0  0" xyz="0    0    0.055"/>
      <geometry>
        <cylinder length="0.05" radius="0.1"/>
      </geometry>
    </collision>
    <visual name="Movee__visual">
      <origin rpy="0  0  0" xyz="0    0    0.065"/>
      <geometry>
        <mesh filename ="package://movee_description/meshes/wheelp.dae" scale="0.001 0.001 0.001"/>
        <!-- <cylinder length="0.05" radius="0.1"/> -->
      </geometry>
    </visual>
  </link>
   <!-- END of Robot description -->


   <!-- Launch the plugin gazebo_ros_control, to enable a the controller_manager to spawn and be able to control the articulations of the robot -->
  <gazebo>
    <plugin name="gazebo_ros_control" filename="libgazebo_ros_control.so">
       <!-- <robotNamespace>/movee</robotNamespace> -->
       <robotSimType>gazebo_ros_control/DefaultRobotHWSim</robotSimType> 
    </plugin>
  </gazebo> 



</robot>
 
  